import 'package:test/test.dart';
import 'package:aqueduct/aqueduct.dart';
import 'dart:async';
import 'package:http/http.dart' as http;

void main() {
  group("Recovers", () {
    var app = new Application<TestChannel>();

    tearDown(() async {
      print("stopping");
      await app?.stop();
      print("stopped");
    });

    test("Application reports uncaught error, recovers", () async {
      await app.start(numberOfInstances: 1);

      // This request will generate an uncaught exception
      var failFuture = http.get("http://localhost:8888/");

      // This request will come in right after the failure but should succeed
      var successFuture = http.get("http://localhost:8888/1");

      // Ensure both requests respond with 200, since the failure occurs asynchronously AFTER the response has been generated
      // for the failure case.
      var successResponse = await successFuture;
      var failResponse = await failFuture;
      expect(successResponse.statusCode, 200);
      expect(failResponse.statusCode, 200);

      var errorMessage = await app.logger.onRecord.first;
      expect(errorMessage.message, contains("Uncaught exception"));
      expect(errorMessage.error.toString(), contains("foo"));
      expect(errorMessage.stackTrace, isNotNull);

      // And then we should make sure everything is working just fine.
      expect((await http.get("http://localhost:8888/1")).statusCode, 200);
    });

    test("Application with multiple isolates reports uncaught error, recovers",
        () async {
      var contents = <String>[];
      int counter = 0;
      var completer = new Completer();
      app.logger.onRecord.listen((rec) {
        print("got msg");
        contents.add(rec.message);
        counter ++;
        if (counter == 5) {
          completer.complete();
        }
      });

      await app.start(numberOfInstances: 2);

      // Throw some deferred crashers then some success messages at the server
      var failFutures = new Iterable.generate(5)
          .map((_) => http.get("http://localhost:8888"));

      var successResponse = await http.get("http://localhost:8888/1");
      expect(successResponse.statusCode, 200);
      expect((await Future.wait(failFutures)).map((r) => r.statusCode),
          everyElement(200));

      print("wait on completion");
      await completer.future;
      print("completed");
      expect(contents.where((c) => c.contains("Uncaught exception")).length, 5);
    });
  });
}

class TestChannel extends ApplicationChannel {
  @override
  Controller get entryPoint {
    final router = new Router();
    router.route("/[:id]").link(() => new UncaughtCrashController());
    return router;
  }
}

class UncaughtCrashController extends ResourceController {
  @Operation.get()
  Future<Response> crashUncaught() async {
    new Future(() {
      var x;
      x.foo();
    });
    return new Response.ok(null);
  }

  @Operation.get("id")
  Future<Response> dontCrash(@Bind.path("id") int id) async {
    return new Response.ok(null);
  }
}
